<?xml version="1.0" ?>
<robot name="task" xmlns:xacro="http://www.ros.org/wiki/xacro">

<xacro:include filename="$(find task_description)/urdf/materials.xacro" />
<xacro:include filename="$(find task_description)/urdf/task.trans" />
<xacro:include filename="$(find task_description)/urdf/task.gazebo" />
<link name="base_link">
  <inertial>
    <origin xyz="0.19428375797350297 0.05335950419749055 -0.05004402179065171" rpy="0 0 0"/>
    <mass value="1.592428354772181"/>
    <inertia ixx="0.001402" iyy="0.006223" izz="0.005395" ixy="-0.000369" iyz="0.0" ixz="-0.0"/>
  </inertial>
  <visual>
    <origin xyz="0 0 0" rpy="0 0 0"/>
    <geometry>
      <mesh filename="package://task_description/meshes/base_link.stl" scale="0.001 0.001 0.001"/>
    </geometry>
    <material name="silver"/>
  </visual>
  <collision>
    <origin xyz="0 0 0" rpy="0 0 0"/>
    <geometry>
      <mesh filename="package://task_description/meshes/base_link.stl" scale="0.001 0.001 0.001"/>
    </geometry>
  </collision>
</link>

<link name="rightwheel_1">
  <inertial>
    <origin xyz="-7.002684170032136e-08 -3.770065234928732e-07 -0.0025000217906516187" rpy="0 0 0"/>
    <mass value="0.1109767604880594"/>
    <inertia ixx="2.5e-05" iyy="2.5e-05" izz="5e-05" ixy="-0.0" iyz="0.0" ixz="-0.0"/>
  </inertial>
  <visual>
    <origin xyz="-0.098227 -0.030091 0.105044" rpy="0 0 0"/>
    <geometry>
      <mesh filename="package://task_description/meshes/rightwheel_1.stl" scale="0.001 0.001 0.001"/>
    </geometry>
    <material name="silver"/>
  </visual>
  <collision>
    <origin xyz="-0.098227 -0.030091 0.105044" rpy="0 0 0"/>
    <geometry>
      <mesh filename="package://task_description/meshes/rightwheel_1.stl" scale="0.001 0.001 0.001"/>
    </geometry>
  </collision>
</link>

<link name="leftwheel_1">
  <inertial>
    <origin xyz="-7.002684158929906e-08 -3.770065233506259e-07 0.0024999782093484742" rpy="0 0 0"/>
    <mass value="0.1109767604880594"/>
    <inertia ixx="2.5e-05" iyy="2.5e-05" izz="5e-05" ixy="-0.0" iyz="0.0" ixz="-0.0"/>
  </inertial>
  <visual>
    <origin xyz="-0.098227 -0.030091 -0.004956" rpy="0 0 0"/>
    <geometry>
      <mesh filename="package://task_description/meshes/leftwheel_1.stl" scale="0.001 0.001 0.001"/>
    </geometry>
    <material name="silver"/>
  </visual>
  <collision>
    <origin xyz="-0.098227 -0.030091 -0.004956" rpy="0 0 0"/>
    <geometry>
      <mesh filename="package://task_description/meshes/leftwheel_1.stl" scale="0.001 0.001 0.001"/>
    </geometry>
  </collision>
</link>

<link name="lidar__1__1">
  <inertial>
    <origin xyz="-7.002684057622055e-08 0.01499962299347668 -2.1790651776043557e-08" rpy="0 0 0"/>
    <mass value="0.46240316870024756"/>
    <inertia ixx="0.000107" iyy="0.000145" izz="0.000107" ixy="-0.0" iyz="0.0" ixz="-0.0"/>
  </inertial>
  <visual>
    <origin xyz="-0.228227 -0.075091 0.050044" rpy="0 0 0"/>
    <geometry>
      <mesh filename="package://task_description/meshes/lidar__1__1.stl" scale="0.001 0.001 0.001"/>
    </geometry>
    <material name="silver"/>
  </visual>
  <collision>
    <origin xyz="-0.228227 -0.075091 0.050044" rpy="0 0 0"/>
    <geometry>
      <mesh filename="package://task_description/meshes/lidar__1__1.stl" scale="0.001 0.001 0.001"/>
    </geometry>
  </collision>
</link>

<joint name="Rev1" type="continuous">
  <origin xyz="0.098227 0.030091 -0.105044" rpy="0 0 0"/>
  <parent link="base_link"/>
  <child link="rightwheel_1"/>
  <axis xyz="0.0 0.0 1.0"/>
</joint>

<joint name="Rev2" type="continuous">
  <origin xyz="0.098227 0.030091 0.004956" rpy="0 0 0"/>
  <parent link="base_link"/>
  <child link="leftwheel_1"/>
  <axis xyz="0.0 0.0 1.0"/>
</joint>

<joint name="Rev5" type="continuous">
  <origin xyz="0.228227 0.075091 -0.050044" rpy="0 0 0"/>
  <parent link="base_link"/>
  <child link="lidar__1__1"/>
  <axis xyz="0.0 1.0 0.0"/>
</joint>

</robot>
